Workbook

Sheet Saldo
A1: Item | C1: Desc. Item | D1: U.M. | E1: UBICACION | F1: Existencia 03-02-25 | G1: Cantidad Ingreso | H1: Cantidad salida | I1: Inventario Actual | K1: OBSERVACION
A2: 0002849 | B2: 017546 | C2: 2914A1805 PATIN | D2: UND | E2: EST.5.2.2 | F2: 3 | G2: =SUMIFS('Entrada - Salida'!$E:$E,'Entrada - Salida'!$D:$D,Saldo!C2,'Entrada - Salida'!C:C,Saldo!B2) -> 4 | H2: =SUMIFS('Entrada - Salida'!$F:$F,'Entrada - Salida'!$D:$D,Saldo!C2,'Entrada - Salida'!C:C,Saldo!B2) -> 3 | I2: =+(G2-H2)+F2 -> 4
A3: 0002850 | B3: 015899 | C3: ABRAZADERA CONDUIT 3/4" | D3: UND | E3: EST.3.8.3 | F3: 5 | G3: =SUMIFS('Entrada - Salida'!$E:$E,'Entrada - Salida'!$D:$D,Saldo!C3,'Entrada - Salida'!C:C,Saldo!B3) -> 0 | H3: =SUMIFS('Entrada - Salida'!$F:$F,'Entrada - Salida'!$D:$D,Saldo!C3,'Entrada - Salida'!C:C,Saldo!B3) -> 5 | I3: =+(G3-H3)+F3 -> 0
A4: 0002851 | B4: 014989 | C4: ABRAZADERA CREMALLERA 1/2" | D4: UND | E4: EST.26.7 | F4: 1 | G4: =SUMIFS('Entrada - Salida'!$E:$E,'Entrada - Salida'!$D:$D,Saldo!C4,'Entrada - Salida'!C:C,Saldo!B4) -> 0 | H4: =SUMIFS('Entrada - Salida'!$F:$F,'Entrada - Salida'!$D:$D,Saldo!C4,'Entrada - Salida'!C:C,Saldo!B4) -> 1 | I4: =+(G4-H4)+F4 -> 0
A5: 0002852 | B5: 014760 | C5: ABRAZADERA CREMALLERA 3" | D5: UND | E5: EST.26.7 | F5: 3 | G5: =SUMIFS('Entrada - Salida'!$E:$E,'Entrada - Salida'!$D:$D,Saldo!C5,'Entrada - Salida'!C:C,Saldo!B5) -> 0 | H5: =SUMIFS('Entrada - Salida'!$F:$F,'Entrada - Salida'!$D:$D,Saldo!C5,'Entrada - Salida'!C:C,Saldo!B5) -> 3 | I5: =+(G5-H5)+F5 -> 0
A6: 0002855 | B6: 017483 | C6: ACCIONADOR 2104A0372 | D6: UND | E6: EST.9.2.4 | F6: 1 | G6: =SUMIFS('Entrada - Salida'!$E:$E,'Entrada - Salida'!$D:$D,Saldo!C6,'Entrada - Salida'!C:C,Saldo!B6) -> 0 | H6: =SUMIFS('Entrada - Salida'!$F:$F,'Entrada - Salida'!$D:$D,Saldo!C6,'Entrada - Salida'!C:C,Saldo!B6) -> 0 | I6: =+(G6-H6)+F6 -> 1
A7: 0002857 | B7: 015467 | C7: ACOPLE CABEZAL 160705400 | D7: UND | E7: EST.18.5.1 | F7: 1 | G7: =SUMIFS('Entrada - Salida'!$E:$E,'Entrada - Salida'!$D:$D,Saldo!C7,'Entrada - Salida'!C:C,Saldo!B7) -> 0 | H7: =SUMIFS('Entrada - Salida'!$F:$F,'Entrada - Salida'!$D:$D,Saldo!C7,'Entrada - Salida'!C:C,Saldo!B7) -> 0 | I7: =+(G7-H7)+F7 -> 1
A8: 0002859 | B8: 014892 | C8: ACOPLE RAPIDO 1/4" DELG | D8: UND | E8: EST.26.6.4 | F8: 1 | G8: =SUMIFS('Entrada - Salida'!$E:$E,'Entrada - Salida'!$D:$D,Saldo!C8,'Entrada - Salida'!C:C,Saldo!B8) -> 0 | H8: =SUMIFS('Entrada - Salida'!$F:$F,'Entrada - Salida'!$D:$D,Saldo!C8,'Entrada - Salida'!C:C,Saldo!B8) -> 0 | I8: =+(G8-H8)+F8 -> 1
A9: 0002861 | B9: 000677 | C9: ACOPLE VALVULA | D9: UND | E9: EST.7.6.2 | F9: 2 | G9: =SUMIFS('Entrada - Salida'!$E:$E,'Entrada - Salida'!$D:$D,Saldo!C9,'Entrada - Salida'!C:C,Saldo!B9) -> 0 | H9: =SUMIFS('Entrada - Salida'!$F:$F,'Entrada - Salida'!$D:$D,Saldo!C9,'Entrada - Salida'!C:C,Saldo!B9) -> 0 | I9: =+(G9-H9)+F9 -> 2
A10: 0002864 | B10: 015767 | C10: ADAPTADOR CILINDRO MACHO | D10: UND | E10: EST.18.2.3 | F10: 2 | G10: =SUMIFS('Entrada - Salida'!$E:$E,'Entrada - Salida'!$D:$D,Saldo!C10,'Entrada - Salida'!C:C,Saldo!B10) -> 0 | H10: =SUMIFS('Entrada - Salida'!$F:$F,'Entrada - Salida'!$D:$D,Saldo!C10,'Entrada - Salida'!C:C,Saldo!B10) -> 0 | I10: =+(G10-H10)+F10 -> 2
A11: 0002866 | B11: 015678 | C11: ALBERO PULE 0807A0376 | D11: UND | E11: EST.18.4.3 | F11: 1 | G11: =SUMIFS('Entrada - Salida'!$E:$E,'Entrada - Salida'!$D:$D,Saldo!C11,'Entrada - Salida'!C:C,Saldo!B11) -> 0 | H11: =SUMIFS('Entrada - Salida'!$F:$F,'Entrada - Salida'!$D:$D,Saldo!C11,'Entrada - Salida'!C:C,Saldo!B11) -> 0 | I11: =+(G11-H11)+F11 -> 1
A12: 0002867 | B12: 007374 | C12: ALIM.SWICHT (2127A0101) | D12: UND | E12: EST.16.2.4 | F12: 1 | G12: =SUMIFS('Entrada - Salida'!$E:$E,'Entrada - Salida'!$D:$D,Saldo!C12,'Entrada - Salida'!C:C,Saldo!B12) -> 0 | H12: =SUMIFS('Entrada - Salida'!$F:$F,'Entrada - Salida'!$D:$D,Saldo!C12,'Entrada - Salida'!C:C,Saldo!B12) -> 0 | I12: =+(G12-H12)+F12 -> 1
A13: 0002871 | B13: 006133 | C13: AMORTIGUADOR X TORNILLO EJE Z(140607900 | D13: UND | E13: EST.7.4.3 | F13: 2 | G13: =SUMIFS('Entrada - Salida'!$E:$E,'Entrada - Salida'!$D:$D,Saldo!C13,'Entrada - Salida'!C:C,Saldo!B13) -> 2 | H13: =SUMIFS('Entrada - Salida'!$F:$F,'Entrada - Salida'!$D:$D,Saldo!C13,'Entrada - Salida'!C:C,Saldo!B13) -> 0 | I13: =+(G13-H13)+F13 -> 4
... A260: 0003530 | B260: 018625 | C260: EMPAQUE GUILLOTINA CURVA BIESSE | D260: UND | E260: EST.10.6.1 | F260: 3 | G260: =SUMIFS('Entrada - Salida'!$E:$E,'Entrada - Salida'!$D:$D,Saldo!C260,'Entrada - Salida'!C:C,Saldo!B260) -> 0 | H260: =SUMIFS('Entrada - Salida'!$F:$F,'Entrada - Salida'!$D:$D,Saldo!C260,'Entrada - Salida'!C:C,Saldo!B260) -> 0 | I260: =+(G260-H260)+F260 -> 3
A261: 0003531 | B261: 015320 | C261: EMPAQUE TIPO D P/CIL | D261: UND | E261: =VLOOKUP(B261,'[1]Base de datos Almacen'!$B$2:$E$3654,4,0) -> EST.4.5.4 | F261: 3 | G261: =SUMIFS('Entrada - Salida'!$E:$E,'Entrada - Salida'!$D:$D,Saldo!C261,'Entrada - Salida'!C:C,Saldo!B261) -> 0 | H261: =SUMIFS('Entrada - Salida'!$F:$F,'Entrada - Salida'!$D:$D,Saldo!C261,'Entrada - Salida'!C:C,Saldo!B261) -> 0 | I261: =+(G261-H261)+F261 -> 3
A262: 0003532 | B262: 015323 | C262: EMPAQUE TIPO K P/CIL | D262: UND | E262: EST.12.3.1 | F262: 1 | G262: =SUMIFS('Entrada - Salida'!$E:$E,'Entrada - Salida'!$D:$D,Saldo!C262,'Entrada - Salida'!C:C,Saldo!B262) -> 0 | H262: =SUMIFS('Entrada - Salida'!$F:$F,'Entrada - Salida'!$D:$D,Saldo!C262,'Entrada - Salida'!C:C,Saldo!B262) -> 0 | I262: =+(G262-H262)+F262 -> 1
A263: 0003533 | B263: 018609 | C263: EMPAQUE VALVULA AKRON | D263: UND | E263: EST.12.4.1 | F263: 4 | G263: =SUMIFS('Entrada - Salida'!$E:$E,'Entrada - Salida'!$D:$D,Saldo!C263,'Entrada - Salida'!C:C,Saldo!B263) -> 0 | H263: =SUMIFS('Entrada - Salida'!$F:$F,'Entrada - Salida'!$D:$D,Saldo!C263,'Entrada - Salida'!C:C,Saldo!B263) -> 0 | I263: =+(G263-H263)+F263 -> 4
A264: 0003534 | B264: 000714 | C264: EMPAQUE VALVULA REF-001 | D264: UND | E264: EST.4.8.5 | F264: 1 | G264: =SUMIFS('Entrada - Salida'!$E:$E,'Entrada - Salida'!$D:$D,Saldo!C264,'Entrada - Salida'!C:C,Saldo!B264) -> 0 | H264: =SUMIFS('Entrada - Salida'!$F:$F,'Entrada - Salida'!$D:$D,Saldo!C264,'Entrada - Salida'!C:C,Saldo!B264) -> 0 | I264: =+(G264-H264)+F264 -> 1
A265: 0003537 | B265: 005244 | C265: EMPUJADOR 141404801 TEHCNO | D265: UND | E265: EST.18.6.1 | F265: 5 | G265: =SUMIFS('Entrada - Salida'!$E:$E,'Entrada - Salida'!$D:$D,Saldo!C265,'Entrada - Salida'!C:C,Saldo!B265) -> 0 | H265: =SUMIFS('Entrada - Salida'!$F:$F,'Entrada - Salida'!$D:$D,Saldo!C265,'Entrada - Salida'!C:C,Saldo!B265) -> 5 | I265: =+(G265-H265)+F265 -> 0
A266: 0003538 | B266: 005719 | C266: ENCODER (H0102D171C0) | D266: UND | E266: EST.18.2.3 | F266: 6 | G266: =SUMIFS('Entrada - Salida'!$E:$E,'Entrada - Salida'!$D:$D,Saldo!C266,'Entrada - Salida'!C:C,Saldo!B266) -> 0 | H266: =SUMIFS('Entrada - Salida'!$F:$F,'Entrada - Salida'!$D:$D,Saldo!C266,'Entrada - Salida'!C:C,Saldo!B266) -> 2 | I266: =+(G266-H266)+F266 -> 4
A267: 0003549 | B267: 004850 | C267: ENGRANAJE HELICOIDAL DE TECHNO 82118200 | D267: UND | E267: EST.11.2.4 | F267: 1 | G267: =SUMIFS('Entrada - Salida'!$E:$E,'Entrada - Salida'!$D:$D,Saldo!C267,'Entrada - Salida'!C:C,Saldo!B267) -> 0 | H267: =SUMIFS('Entrada - Salida'!$F:$F,'Entrada - Salida'!$D:$D,Saldo!C267,'Entrada - Salida'!C:C,Saldo!B267) -> 0 | I267: =+(G267-H267)+F267 -> 1
A268: 0003550 | B268: 005391 | C268: ENGRANAJE HELICOIDAL SETEHCNO (82118500 | D268: UND | E268: EST.11.4.2 | F268: 60 | G268: =SUMIFS('Entrada - Salida'!$E:$E,'Entrada - Salida'!$D:$D,Saldo!C268,'Entrada - Salida'!C:C,Saldo!B268) -> 0 | H268: =SUMIFS('Entrada - Salida'!$F:$F,'Entrada - Salida'!$D:$D,Saldo!C268,'Entrada - Salida'!C:C,Saldo!B268) -> 0 | I268: =+(G268-H268)+F268 -> 60
A269: 0003551 | B269: 004849 | C269: ENGRANAJE HELICOIDAL SX TECHNO(82118400 | D269: UND | E269: EST.11.2.2 | F269: 1 | G269: =SUMIFS('Entrada - Salida'!$E:$E,'Entrada - Salida'!$D:$D,Saldo!C269,'Entrada - Salida'!C:C,Saldo!B269) -> 0 | H269: =SUMIFS('Entrada - Salida'!$F:$F,'Entrada - Salida'!$D:$D,Saldo!C269,'Entrada - Salida'!C:C,Saldo!B269) -> 0 | I269: =+(G269-H269)+F269 -> 1
A270: 0003552 | B270: 004847 | C270: ENGRANAJE HELICOIDAL TECHNO (82118300) | D270: UND | E270: EST.11.5.2 | F270: 59 | G270: =SUMIFS('Entrada - Salida'!$E:$E,'Entrada - Salida'!$D:$D,Saldo!C270,'Entrada - Salida'!C:C,Saldo!B270) -> 0 | H270: =SUMIFS('Entrada - Salida'!$F:$F,'Entrada - Salida'!$D:$D,Saldo!C270,'Entrada - Salida'!C:C,Saldo!B270) -> 0 | I270: =+(G270-H270)+F270 -> 59
A271: 0003553 | B271: 015422 | C271: ENGRANAJE MOTOR CABEZAL 082108803 | D271: UND | E271: EST.19.4.3 | F271: 1 | G271: =SUMIFS('Entrada - Salida'!$E:$E,'Entrada - Salida'!$D:$D,Saldo!C271,'Entrada - Salida'!C:C,Saldo!B271) -> 0 | H271: =SUMIFS('Entrada - Salida'!$F:$F,'Entrada - Salida'!$D:$D,Saldo!C271,'Entrada - Salida'!C:C,Saldo!B271) -> 0 | I271: =+(G271-H271)+F271 -> 1
A272: 0003555 | B272: 007008 | C272: ENGRANE CONICO (142100100) | D272: UND | E272: EST.11.3.1 | F272: 4 | G272: =SUMIFS('Entrada - Salida'!$E:$E,'Entrada - Salida'!$D:$D,Saldo!C272,'Entrada - Salida'!C:C,Saldo!B272) -> 0 | H272: =SUMIFS('Entrada - Salida'!$F:$F,'Entrada - Salida'!$D:$D,Saldo!C272,'Entrada - Salida'!C:C,Saldo!B272) -> 0 | I272: =+(G272-H272)+F272 -> 4
A273: 0003556 | B273: 007009 | C273: ENGRANE CONICO (142100201) | D273: UND | E273: EST.11.3.1 | F273: 10 | G273: =SUMIFS('Entrada - Salida'!$E:$E,'Entrada - Salida'!$D:$D,Saldo!C273,'Entrada - Salida'!C:C,Saldo!B273) -> 0 | H273: =SUMIFS('Entrada - Salida'!$F:$F,'Entrada - Salida'!$D:$D,Saldo!C273,'Entrada - Salida'!C:C,Saldo!B273) -> 1 | I273: =+(G273-H273)+F273 -> 9
... A306: 0003644 | B306: 015880 | C306: FUSIBLE CRISTAL 10A 5x30 | D306: UND | E306: EST.2.7.2 | F306: 5 | G306: =SUMIFS('Entrada - Salida'!$E:$E,'Entrada - Salida'!$D:$D,Saldo!C306,'Entrada - Salida'!C:C,Saldo!B306) -> 0 | H306: =SUMIFS('Entrada - Salida'!$F:$F,'Entrada - Salida'!$D:$D,Saldo!C306,'Entrada - Salida'!C:C,Saldo!B306) -> 0 | I306: =+(G306-H306)+F306 -> 5
A307: 0003645 | B307: 015881 | C307: FUSIBLE CRISTAL 15A 5x30 | D307: UND | E307: EST.2.7.2 | G307: =SUMIFS('Entrada - Salida'!$E:$E,'Entrada - Salida'!$D:$D,Saldo!C307,'Entrada - Salida'!C:C,Saldo!B307) -> 5 | H307: =SUMIFS('Entrada - Salida'!$F:$F,'Entrada - Salida'!$D:$D,Saldo!C307,'Entrada - Salida'!C:C,Saldo!B307) -> 0 | I307: =+(G307-H307)+F307 -> 5
A308: 0003646 | B308: 015365 | C308: FUSIBLE CRISTAL 2A 4x20 | D308: UND | E308: EST.2.7.2 | F308: 6 | G308: =SUMIFS('Entrada - Salida'!$E:$E,'Entrada - Salida'!$D:$D,Saldo!C308,'Entrada - Salida'!C:C,Saldo!B308) -> 0 | H308: =SUMIFS('Entrada - Salida'!$F:$F,'Entrada - Salida'!$D:$D,Saldo!C308,'Entrada - Salida'!C:C,Saldo!B308) -> 0 | I308: =+(G308-H308)+F308 -> 6
A309: 0003647 | B309: 015600 | C309: FUSIBLE CRISTAL 2A 5x30 | D309: UND | E309: EST.2.7.2 | F309: 5 | G309: =SUMIFS('Entrada - Salida'!$E:$E,'Entrada - Salida'!$D:$D,Saldo!C309,'Entrada - Salida'!C:C,Saldo!B309) -> 0 | H309: =SUMIFS('Entrada - Salida'!$F:$F,'Entrada - Salida'!$D:$D,Saldo!C309,'Entrada - Salida'!C:C,Saldo!B309) -> 0 | I309: =+(G309-H309)+F309 -> 5
A310: 0003648 | B310: 015671 | C310: FUSIBLE CRISTAL 4A 4x20 | D310: UND | E310: EST.2.7.2 | F310: 5 | G310: =SUMIFS('Entrada - Salida'!$E:$E,'Entrada - Salida'!$D:$D,Saldo!C310,'Entrada - Salida'!C:C,Saldo!B310) -> 0 | H310: =SUMIFS('Entrada - Salida'!$F:$F,'Entrada - Salida'!$D:$D,Saldo!C310,'Entrada - Salida'!C:C,Saldo!B310) -> 2 | I310: =+(G310-H310)+F310 -> 3
A311: 0003649 | B311: 015603 | C311: FUSIBLE CRISTAL 4A 5x30 | D311: UND | E311: EST.2.7.2 | F311: 6 | G311: =SUMIFS('Entrada - Salida'!$E:$E,'Entrada - Salida'!$D:$D,Saldo!C311,'Entrada - Salida'!C:C,Saldo!B311) -> 10 | H311: =SUMIFS('Entrada - Salida'!$F:$F,'Entrada - Salida'!$D:$D,Saldo!C311,'Entrada - Salida'!C:C,Saldo!B311) -> 6 | I311: =+(G311-H311)+F311 -> 10
A312: 0003650 | B312: 015459 | C312: FUSIBLE CRISTAL 5A 4x20 | D312: UND | E312: EST.2.7.2 | F312: 1 | G312: =SUMIFS('Entrada - Salida'!$E:$E,'Entrada - Salida'!$D:$D,Saldo!C312,'Entrada - Salida'!C:C,Saldo!B312) -> 0 | H312: =SUMIFS('Entrada - Salida'!$F:$F,'Entrada - Salida'!$D:$D,Saldo!C312,'Entrada - Salida'!C:C,Saldo!B312) -> 0 | I312: =+(G312-H312)+F312 -> 1
A313: 0003651 | B313: 015643 | C313: FUSIBLE DIAZED 6A | D313: UND | E313: EST.2.10.4 | F313: 4 | G313: =SUMIFS('Entrada - Salida'!$E:$E,'Entrada - Salida'!$D:$D,Saldo!C313,'Entrada - Salida'!C:C,Saldo!B313) -> 0 | H313: =SUMIFS('Entrada - Salida'!$F:$F,'Entrada - Salida'!$D:$D,Saldo!C313,'Entrada - Salida'!C:C,Saldo!B313) -> 0 | I313: =+(G313-H313)+F313 -> 4
A314: 0003652 | B314: 015601 | C314: FUSIBLE VEHICULO 10A | D314: UND | E314: EST.2.7.2 | F314: 1 | G314: =SUMIFS('Entrada - Salida'!$E:$E,'Entrada - Salida'!$D:$D,Saldo!C314,'Entrada - Salida'!C:C,Saldo!B314) -> 0 | H314: =SUMIFS('Entrada - Salida'!$F:$F,'Entrada - Salida'!$D:$D,Saldo!C314,'Entrada - Salida'!C:C,Saldo!B314) -> 0 | I314: =+(G314-H314)+F314 -> 1
A315: 0003653 | B315: 015406 | C315: FUSIBLE VEHICULO 15A | D315: UND | E315: EST.2.7.2 | F315: 6 | G315: =SUMIFS('Entrada - Salida'!$E:$E,'Entrada - Salida'!$D:$D,Saldo!C315,'Entrada - Salida'!C:C,Saldo!B315) -> 0 | H315: =SUMIFS('Entrada - Salida'!$F:$F,'Entrada - Salida'!$D:$D,Saldo!C315,'Entrada - Salida'!C:C,Saldo!B315) -> 1 | I315: =+(G315-H315)+F315 -> 5
A316: 0003655 | B316: 005623 | C316: GHIERA FISSAG.VC (N0836N0043) | D316: UND | E316: EST.16.4.3 | F316: 1 | G316: =SUMIFS('Entrada - Salida'!$E:$E,'Entrada - Salida'!$D:$D,Saldo!C316,'Entrada - Salida'!C:C,Saldo!B316) -> 0 | H316: =SUMIFS('Entrada - Salida'!$F:$F,'Entrada - Salida'!$D:$D,Saldo!C316,'Entrada - Salida'!C:C,Saldo!B316) -> 0 | I316: =+(G316-H316)+F316 -> 1
A317: 0003656 | B317: 014631 | C317: GHIERA M50x1.5 AUTOBLOC 301702400 | D317: UND | E317: EST.5.3.2 | F317: 1 | G317: =SUMIFS('Entrada - Salida'!$E:$E,'Entrada - Salida'!$D:$D,Saldo!C317,'Entrada - Salida'!C:C,Saldo!B317) -> 0 | H317: =SUMIFS('Entrada - Salida'!$F:$F,'Entrada - Salida'!$D:$D,Saldo!C317,'Entrada - Salida'!C:C,Saldo!B317) -> 0 | I317: =+(G317-H317)+F317 -> 1
A318: 0003658 | B318: 017153 | C318: GLYCODUR PBG 12-14-12 F - 2910A0129 | D318: UND | E318: EST.9.3.2 | F318: 8 | G318: =SUMIFS('Entrada - Salida'!$E:$E,'Entrada - Salida'!$D:$D,Saldo!C318,'Entrada - Salida'!C:C,Saldo!B318) -> 20 | H318: =SUMIFS('Entrada - Salida'!$F:$F,'Entrada - Salida'!$D:$D,Saldo!C318,'Entrada - Salida'!C:C,Saldo!B318) -> 0 | I318: =+(G318-H318)+F318 -> 28
...

Sheet Entrada - Salida
A1: Fecha Ingreso | B1: Fecha Salida | C1: Referencia | D1: Desc. Item | E1: Cantidad Ingreso | F1: Cantidad salida | G1: Observacion
A2: 45692 | C2: 0007527 | D2: =IF(C2="","",IFERROR(VLOOKUP(C2,Saldo!$B$1:$C$9915,2,0),"CREAR EN SALDO")) -> CINTA ROTULADORA 12MM DYMO | E2: 4 | G2: EA 17969
A3: 45692 | C3: 0011316 | D3: =IF(C3="","",IFERROR(VLOOKUP(C3,Saldo!$B$1:$C$9915,2,0),"CREAR EN SALDO")) -> VENTILADOR 220X220X60 MM 200-240VAC ROD | E3: 2 | G3: EA 17969
C4: 005339 | D4: =IF(C4="","",IFERROR(VLOOKUP(C4,Saldo!$B$1:$C$9915,2,0),"CREAR EN SALDO")) -> JUNTA CARDAN REDUCTOR RODILLO PRESION | E4: 1
A5: 45692 | C5: 0011317 | D5: =IF(C5="","",IFERROR(VLOOKUP(C5,Saldo!$B$1:$C$9915,2,0),"CREAR EN SALDO")) -> MEDIDOR DE VIBRACIONES ACEL/VELOC/DESPL | E5: 1 | G5: EA 17970
A6: 45692 | C6: 0011318 | D6: =IF(C6="","",IFERROR(VLOOKUP(C6,Saldo!$B$1:$C$9915,2,0),"CREAR EN SALDO")) -> CAMARA TERMOGRAFIA INFRA. RESO.160X120 | E6: 1 | G6: EA 17970
A7: 45692 | C7: 018637 | D7: =IF(C7="","",IFERROR(VLOOKUP(C7,Saldo!$B$1:$C$9915,2,0),"CREAR EN SALDO")) -> CONECTOR DE 4 PINES ROVER | E7: 4 | G7: EA 17971
A8: 45692 | C8: 0011207 | D8: =IF(C8="","",IFERROR(VLOOKUP(C8,Saldo!$B$1:$C$9915,2,0),"CREAR EN SALDO")) -> VENTILADOR DE GABINETE 6" 115/220V | E8: 2 | G8: EA 17972
A9: 45692 | C9: 0011332 | D9: =IF(C9="","",IFERROR(VLOOKUP(C9,Saldo!$B$1:$C$9915,2,0),"CREAR EN SALDO")) -> CONECTOR M12 5MTS 4H 164264 SCHMERSAL | E9: 2 | G9: EA 17972
A10: 45692 | C10: 0008534 | D10: =IF(C10="","",IFERROR(VLOOKUP(C10,Saldo!$B$1:$C$9915,2,0),"CREAR EN SALDO")) -> CLAVIJA 4X32 AZUL TCV0038 | E10: 4 | G10: EA 17973
A11: 45692 | C11: 0007297 | D11: =IF(C11="","",IFERROR(VLOOKUP(C11,Saldo!$B$1:$C$9915,2,0),"CREAR EN SALDO")) -> 2701A0344-CORREA L=1264-8MGT-30.SC-WNT | E11: 3 | G11: EA 17974
A12: 45692 | C12: 0008300 | D12: =IF(C12="","",IFERROR(VLOOKUP(C12,Saldo!$B$1:$C$9915,2,0),"CREAR EN SALDO")) -> TUERCA SEGURIDAD M8 | E12: 100 | G12: EA 17977
A13: 45693 | C13: 0006901 | D13: =IF(C13="","",IFERROR(VLOOKUP(C13,Saldo!$B$1:$C$9915,2,0),"CREAR EN SALDO")) -> 290102300 RODAMIENTO 6001 2RS1 12- 28 | E13: 8 | G13: EA 17978
A14: 45693 | C14: 0005526 | D14: =IF(C14="","",IFERROR(VLOOKUP(C14,Saldo!$B$1:$C$9915,2,0),"CREAR EN SALDO")) -> RODAMIENTO DE AGUJAS NK 18/16 | E14: 4 | G14: EA 17979
A15: 45693 | C15: 0006254 | D15: =IF(C15="","",IFERROR(VLOOKUP(C15,Saldo!$B$1:$C$9915,2,0),"CREAR EN SALDO")) -> 290101900 RODAMIENTO 6003 2RS1 17- 35- 1 | E15: 6 | G15: EA 17979
A16: 45693 | C16: 0009354 | D16: =IF(C16="","",IFERROR(VLOOKUP(C16,Saldo!$B$1:$C$9915,2,0),"CREAR EN SALDO")) -> RODAMIENTO 22209-E1-XL-K-C3 | E16: 2 | G16: EA 17980
A17: 45693 | C17: 015742 | D17: =IF(C17="","",IFERROR(VLOOKUP(C17,Saldo!$B$1:$C$9915,2,0),"CREAR EN SALDO")) -> MANGUITO H309 | E17: 2 | G17: EA 17980
B18: 45693 | C18: 0009021 | D18: =IF(C18="","",IFERROR(VLOOKUP(C18,Saldo!$B$1:$C$9915,2,0),"CREAR EN SALDO")) -> 13300020 ARO TORICO.BEA | F18: 1 | G18: SA 17091
B19: 45693 | C19: 0009131 | D19: =IF(C19="","",IFERROR(VLOOKUP(C19,Saldo!$B$1:$C$9915,2,0),"CREAR EN SALDO")) -> ESTACION DE MANDO 25600 | F19: 2 | G19: SA 17091
B20: 45693 | C20: 0009157 | D20: =IF(C20="","",IFERROR(VLOOKUP(C20,Saldo!$B$1:$C$9915,2,0),"CREAR EN SALDO")) -> 2104A0208 INTERRUPTOR | F20: 2 | G20: SA 17091
B21: 45693 | C21: 0005085 | D21: =IF(C21="","",IFERROR(VLOOKUP(C21,Saldo!$B$1:$C$9915,2,0),"CREAR EN SALDO")) -> MANGUERA POLIURETANO COBRIZADA. DE 2" | F21: 9 | G21: SA 17091
B22: 45693 | C22: 0008288 | D22: =IF(C22="","",IFERROR(VLOOKUP(C22,Saldo!$B$1:$C$9915,2,0),"CREAR EN SALDO")) -> TUERCA HEX 6.6 M5-0.8 | F22: 4 | G22: SA 17091
B23: 45693 | C23: 0010476 | D23: =IF(C23="","",IFERROR(VLOOKUP(C23,Saldo!$B$1:$C$9915,2,0),"CREAR EN SALDO")) -> CREAR EN SALDO | F23: 2 | G23: SA 17091
B24: 45693 | C24: 0008217 | D24: =IF(C24="","",IFERROR(VLOOKUP(C24,Saldo!$B$1:$C$9915,2,0),"CREAR EN SALDO")) -> CREAR EN SALDO | F24: 2 | G24: SA 17091
B25: 45693 | C25: 0008211 | D25: =IF(C25="","",IFERROR(VLOOKUP(C25,Saldo!$B$1:$C$9915,2,0),"CREAR EN SALDO")) -> TORNILLO BCC 5X20MM | F25: 4 | G25: SA 17091
B26: 45693 | C26: 0008196 | D26: =IF(C26="","",IFERROR(VLOOKUP(C26,Saldo!$B$1:$C$9915,2,0),"CREAR EN SALDO")) -> CREAR EN SALDO | F26: 2 | G26: SA 17091
B27: 45693 | C27: 0008306 | D27: =IF(C27="","",IFERROR(VLOOKUP(C27,Saldo!$B$1:$C$9915,2,0),"CREAR EN SALDO")) -> ARANDELA PLANA M3 DIN125 | F27: 4 | G27: SA 17091
B28: 45693 | C28: 0008633 | D28: =IF(C28="","",IFERROR(VLOOKUP(C28,Saldo!$B$1:$C$9915,2,0),"CREAR EN SALDO")) -> ARANDELA PLANA 5.3X15X1.25MM DIN 522 | F28: 4 | G28: SA 17091
B29: 45693 | C29: 0010502 | D29: =IF(C29="","",IFERROR(VLOOKUP(C29,Saldo!$B$1:$C$9915,2,0),"CREAR EN SALDO")) -> REDUCCION BUCHING 1/4 X 3/8 | F29: 2 | G29: SA 17091
... B41: 45693 | C41: 0003684 | D41: =IF(C41="","",IFERROR(VLOOKUP(C41,Saldo!$B$1:$C$9915,2,0),"CREAR EN SALDO")) -> 750123360 GUARNICION O VINILO.ROVER | F41: 4 | G41: SA 17091
B42: 45693 | C42: 0005088 | D42: =IF(C42="","",IFERROR(VLOOKUP(C42,Saldo!$B$1:$C$9915,2,0),"CREAR EN SALDO")) -> MANGUERA POLIURETANO COBRIZADA. DE 8" | F42: 5.85 | G42: SA 17091
B43: 45693 | C43: 0007881 | D43: =IF(C43="","",IFERROR(VLOOKUP(C43,Saldo!$B$1:$C$9915,2,0),"CREAR EN SALDO")) -> RACOR UNION EN Y 12MM OD | F43: 7 | G43: SA 17091
B44: 45693 | C44: 0005526 | D44: =IF(C44="","",IFERROR(VLOOKUP(C44,Saldo!$B$1:$C$9915,2,0),"CREAR EN SALDO")) -> RODAMIENTO DE AGUJAS NK 18/16 | F44: 1 | G44: SA 17091
B45: 45693 | C45: 0007297 | D45: =IF(C45="","",IFERROR(VLOOKUP(C45,Saldo!$B$1:$C$9915,2,0),"CREAR EN SALDO")) -> 2701A0344-CORREA L=1264-8MGT-30.SC-WNT | F45: 1 | G45: SA 17091
B46: 45693 | C46: 015742 | D46: =IF(C46="","",IFERROR(VLOOKUP(C46,Saldo!$B$1:$C$9915,2,0),"CREAR EN SALDO")) -> MANGUITO H309 | F46: 2 | G46: SA 17091
B47: 45693 | C47: 0009354 | D47: =IF(C47="","",IFERROR(VLOOKUP(C47,Saldo!$B$1:$C$9915,2,0),"CREAR EN SALDO")) -> RODAMIENTO 22209-E1-XL-K-C3 | F47: 2 | G47: SA 17091
B48: 45693 | C48: 0006254 | D48: =IF(C48="","",IFERROR(VLOOKUP(C48,Saldo!$B$1:$C$9915,2,0),"CREAR EN SALDO")) -> 290101900 RODAMIENTO 6003 2RS1 17- 35- 1 | F48: 1 | G48: SA 17091
B49: 45693 | C49: 0008136 | D49: =IF(C49="","",IFERROR(VLOOKUP(C49,Saldo!$B$1:$C$9915,2,0),"CREAR EN SALDO")) -> LUBRICANTE CRC GRAFITO MOLIBDENO 430ml | F49: 1 | G49: SA 17091
B50: 45693 | C50: 0006000 | D50: =IF(C50="","",IFERROR(VLOOKUP(C50,Saldo!$B$1:$C$9915,2,0),"CREAR EN SALDO")) -> CSAL130020 CORREA L=20560 W | F50: 1 | G50: SA 17091
B51: 45693 | C51: 0009575 | D51: =IF(C51="","",IFERROR(VLOOKUP(C51,Saldo!$B$1:$C$9915,2,0),"CREAR EN SALDO")) -> CREAR EN SALDO | F51: 4 | G51: SA 17091
...
